[2025-03-28 22:10:05,326][__main__][DEBUG] - Running __main__ in /Users/ammaraljerwi/research/deepsphere-adams/main_deepsphere.py
[2025-03-28 22:10:05,326][cmbml.core.log_maker][DEBUG] - Running cmbml.core.log_maker in /Users/ammaraljerwi/anaconda3/envs/cmb-ml/lib/python3.9/site-packages/cmbml/core/log_maker.py
[2025-03-28 22:10:05,334][cmbml.core.log_maker][WARNING] - File referenced in a defaults was not found: /Users/ammaraljerwi/research/deepsphere-adams/cfg/pipeline/assembly_deepsphere.yaml for line assembly_sim
[2025-03-28 22:10:05,334][cmbml.core.log_maker][WARNING] - File referenced in a defaults was not found: /Users/ammaraljerwi/research/deepsphere-adams/cfg/pipeline/assembly_deepsphere.yaml for line pipe_model_analysis
[2025-03-28 22:10:05,420][stages][INFO] - Performing pre-run checks. Trying __init__() method for each stage to check for obvious issues.
[2025-03-28 22:10:05,420][stages][INFO] - Checking initialization for: HydraConfigCheckerExecutor
[2025-03-28 22:10:05,422][stages][INFO] - Checking initialization for: DeterministicTrainingExecutor
[2025-03-28 22:10:05,440][deepsphere_unet.stage_executors.B_train_deterministic_model][INFO] - MPS is not supported for sparse models. Using CPU.
[2025-03-28 22:10:05,441][stages][INFO] - Checking initialization for: PredictionExecutor
[2025-03-28 22:10:05,446][deepsphere_unet.stage_executors.C_predict_deterministic][INFO] - MPS is not supported for sparse models. Using CPU.
[2025-03-28 22:10:05,446][stages][INFO] - Checking initialization for: BayesianTrainingExecutor
[2025-03-28 22:10:05,451][deepsphere_unet.stage_executors.D_train_bayesian_model][INFO] - MPS is not supported for sparse models. Using CPU.
[2025-03-28 22:10:05,451][stages][INFO] - Checking initialization for: BayesianPredictionExecutor
[2025-03-28 22:10:05,456][deepsphere_unet.stage_executors.E_predict_bayesian][INFO] - MPS is not supported for sparse models. Using CPU.
[2025-03-28 22:10:05,456][stages][INFO] - Pre-run checks complete.
[2025-03-28 22:10:05,456][stages][INFO] - Running stage: HydraConfigCheckerExecutor
[2025-03-28 22:10:05,463][cmbml.core.A_check_hydra_configs][DEBUG] - No conflict in Hydra Configs found.
[2025-03-28 22:10:05,463][stages][INFO] - Done running stage: HydraConfigCheckerExecutor
[2025-03-28 22:10:05,463][stages][WARNING] - Skipping stage logs for stage HydraConfigCheckerExecutor.
[2025-03-28 22:10:05,463][stages][INFO] - Running stage: DeterministicTrainingExecutor
[2025-03-28 22:10:05,468][deepsphere_unet.stage_executors.B_train_deterministic_model][INFO] - MPS is not supported for sparse models. Using CPU.
[2025-03-28 22:10:05,468][deepsphere_unet.stage_executors.B_train_deterministic_model][DEBUG] - Running DeterministicTrainingExecutor execute()
[2025-03-28 22:10:05,468][deepsphere_unet.stage_executors.B_train_deterministic_model][INFO] - Creating model using detectors: 30, 44, 70, 100, 143, 217, 353, 545, 857
[2025-03-28 22:10:05,468][deepsphere_unet.stage_executors.B_train_deterministic_model][INFO] - Using static learning rate.
[2025-03-28 22:10:05,468][deepsphere_unet.stage_executors.B_train_deterministic_model][INFO] - Learning rate is 0.001
[2025-03-28 22:10:05,468][deepsphere_unet.stage_executors.B_train_deterministic_model][INFO] - Number of epochs is 200
[2025-03-28 22:10:05,468][deepsphere_unet.stage_executors.B_train_deterministic_model][INFO] - Batch size is 11
[2025-03-28 22:10:05,468][deepsphere_unet.stage_executors.B_train_deterministic_model][INFO] - Checkpoint every 5 iterations
[2025-03-28 22:10:05,468][deepsphere_unet.stage_executors.B_train_deterministic_model][INFO] - Extra check is set to [1, 2, 3, 6, 9]
[2025-03-28 22:10:05,469][deepsphere_unet.stage_executors.B_train_deterministic_model][INFO] - Inspecting data for Train split: 
[2025-03-28 22:10:05,478][stages][ERROR] - An exception occurred during stage: DeterministicTrainingExecutor
Traceback (most recent call last):
  File "/Users/ammaraljerwi/anaconda3/envs/cmb-ml/lib/python3.9/site-packages/cmbml/core/asset_handlers/healpy_map_handler.py", line 45, in read
    this_map: np.ndarray = hp.read_map(path, field=map_fields, nest=read_to_nest)
  File "/Users/ammaraljerwi/anaconda3/envs/cmb-ml/lib/python3.9/site-packages/astropy/utils/decorators.py", line 604, in wrapper
    return function(*args, **kwargs)
  File "/Users/ammaraljerwi/anaconda3/envs/cmb-ml/lib/python3.9/site-packages/healpy/fitsfunc.py", line 369, in read_map
    filename = pf.open(filename, memmap=memmap)
  File "/Users/ammaraljerwi/anaconda3/envs/cmb-ml/lib/python3.9/site-packages/astropy/io/fits/hdu/hdulist.py", line 222, in fitsopen
    return HDUList.fromfile(
  File "/Users/ammaraljerwi/anaconda3/envs/cmb-ml/lib/python3.9/site-packages/astropy/io/fits/hdu/hdulist.py", line 486, in fromfile
    return cls._readfrom(
  File "/Users/ammaraljerwi/anaconda3/envs/cmb-ml/lib/python3.9/site-packages/astropy/io/fits/hdu/hdulist.py", line 1169, in _readfrom
    fileobj = _File(
  File "/Users/ammaraljerwi/anaconda3/envs/cmb-ml/lib/python3.9/site-packages/astropy/io/fits/file.py", line 218, in __init__
    self._open_filename(fileobj, mode, overwrite)
  File "/Users/ammaraljerwi/anaconda3/envs/cmb-ml/lib/python3.9/site-packages/astropy/io/fits/file.py", line 641, in _open_filename
    self._file = open(self.name, IO_FITS_MODES[mode])
FileNotFoundError: [Errno 2] No such file or directory: '/Users/ammaraljerwi/research/space/Datasets/I_32_2-2/Simulation/Train/sim0000/obs_30_map.fits'

During handling of the above exception, another exception occurred:

Traceback (most recent call last):
  File "/Users/ammaraljerwi/anaconda3/envs/cmb-ml/lib/python3.9/site-packages/cmbml/core/pipeline_context.py", line 75, in _run_executor
    executor.execute()
  File "/Users/ammaraljerwi/research/deepsphere-adams/deepsphere_unet/stage_executors/B_train_deterministic_model.py", line 94, in execute
    self.inspect_data(train_dataloader)
  File "/Users/ammaraljerwi/research/deepsphere-adams/deepsphere_unet/stage_executors/B_train_deterministic_model.py", line 266, in inspect_data
    train_features, train_labels = next(iter(dataloader))
  File "/Users/ammaraljerwi/anaconda3/envs/cmb-ml/lib/python3.9/site-packages/torch/utils/data/dataloader.py", line 708, in __next__
    data = self._next_data()
  File "/Users/ammaraljerwi/anaconda3/envs/cmb-ml/lib/python3.9/site-packages/torch/utils/data/dataloader.py", line 764, in _next_data
    data = self._dataset_fetcher.fetch(index)  # may raise StopIteration
  File "/Users/ammaraljerwi/anaconda3/envs/cmb-ml/lib/python3.9/site-packages/torch/utils/data/_utils/fetch.py", line 52, in fetch
    data = [self.dataset[idx] for idx in possibly_batched_index]
  File "/Users/ammaraljerwi/anaconda3/envs/cmb-ml/lib/python3.9/site-packages/torch/utils/data/_utils/fetch.py", line 52, in <listcomp>
    data = [self.dataset[idx] for idx in possibly_batched_index]
  File "/Users/ammaraljerwi/research/deepsphere-adams/deepsphere_unet/dataset.py", line 29, in __getitem__
    features = _get_features_idx(freqs=self.freqs,
  File "/Users/ammaraljerwi/research/deepsphere-adams/deepsphere_unet/dataset.py", line 103, in _get_features_idx
    feature_data = handler.read(feature_path)
  File "/Users/ammaraljerwi/anaconda3/envs/cmb-ml/lib/python3.9/site-packages/cmbml/core/asset_handlers/healpy_map_handler.py", line 58, in read
    raise FileNotFoundError(f"This map file cannot be found: {path}")
FileNotFoundError: This map file cannot be found: /Users/ammaraljerwi/research/space/Datasets/I_32_2-2/Simulation/Train/sim0000/obs_30_map.fits
[2025-03-28 22:10:05,486][__main__][ERROR] - An exception occured during the pipeline.
Traceback (most recent call last):
  File "/Users/ammaraljerwi/anaconda3/envs/cmb-ml/lib/python3.9/site-packages/cmbml/core/asset_handlers/healpy_map_handler.py", line 45, in read
    this_map: np.ndarray = hp.read_map(path, field=map_fields, nest=read_to_nest)
  File "/Users/ammaraljerwi/anaconda3/envs/cmb-ml/lib/python3.9/site-packages/astropy/utils/decorators.py", line 604, in wrapper
    return function(*args, **kwargs)
  File "/Users/ammaraljerwi/anaconda3/envs/cmb-ml/lib/python3.9/site-packages/healpy/fitsfunc.py", line 369, in read_map
    filename = pf.open(filename, memmap=memmap)
  File "/Users/ammaraljerwi/anaconda3/envs/cmb-ml/lib/python3.9/site-packages/astropy/io/fits/hdu/hdulist.py", line 222, in fitsopen
    return HDUList.fromfile(
  File "/Users/ammaraljerwi/anaconda3/envs/cmb-ml/lib/python3.9/site-packages/astropy/io/fits/hdu/hdulist.py", line 486, in fromfile
    return cls._readfrom(
  File "/Users/ammaraljerwi/anaconda3/envs/cmb-ml/lib/python3.9/site-packages/astropy/io/fits/hdu/hdulist.py", line 1169, in _readfrom
    fileobj = _File(
  File "/Users/ammaraljerwi/anaconda3/envs/cmb-ml/lib/python3.9/site-packages/astropy/io/fits/file.py", line 218, in __init__
    self._open_filename(fileobj, mode, overwrite)
  File "/Users/ammaraljerwi/anaconda3/envs/cmb-ml/lib/python3.9/site-packages/astropy/io/fits/file.py", line 641, in _open_filename
    self._file = open(self.name, IO_FITS_MODES[mode])
FileNotFoundError: [Errno 2] No such file or directory: '/Users/ammaraljerwi/research/space/Datasets/I_32_2-2/Simulation/Train/sim0000/obs_30_map.fits'

During handling of the above exception, another exception occurred:

Traceback (most recent call last):
  File "/Users/ammaraljerwi/research/deepsphere-adams/main_deepsphere.py", line 54, in run_deepsphere
    pipeline_context.run_pipeline()
  File "/Users/ammaraljerwi/anaconda3/envs/cmb-ml/lib/python3.9/site-packages/cmbml/core/pipeline_context.py", line 59, in run_pipeline
    self._run_executor(executor)
  File "/Users/ammaraljerwi/anaconda3/envs/cmb-ml/lib/python3.9/site-packages/cmbml/core/pipeline_context.py", line 79, in _run_executor
    raise e
  File "/Users/ammaraljerwi/anaconda3/envs/cmb-ml/lib/python3.9/site-packages/cmbml/core/pipeline_context.py", line 75, in _run_executor
    executor.execute()
  File "/Users/ammaraljerwi/research/deepsphere-adams/deepsphere_unet/stage_executors/B_train_deterministic_model.py", line 94, in execute
    self.inspect_data(train_dataloader)
  File "/Users/ammaraljerwi/research/deepsphere-adams/deepsphere_unet/stage_executors/B_train_deterministic_model.py", line 266, in inspect_data
    train_features, train_labels = next(iter(dataloader))
  File "/Users/ammaraljerwi/anaconda3/envs/cmb-ml/lib/python3.9/site-packages/torch/utils/data/dataloader.py", line 708, in __next__
    data = self._next_data()
  File "/Users/ammaraljerwi/anaconda3/envs/cmb-ml/lib/python3.9/site-packages/torch/utils/data/dataloader.py", line 764, in _next_data
    data = self._dataset_fetcher.fetch(index)  # may raise StopIteration
  File "/Users/ammaraljerwi/anaconda3/envs/cmb-ml/lib/python3.9/site-packages/torch/utils/data/_utils/fetch.py", line 52, in fetch
    data = [self.dataset[idx] for idx in possibly_batched_index]
  File "/Users/ammaraljerwi/anaconda3/envs/cmb-ml/lib/python3.9/site-packages/torch/utils/data/_utils/fetch.py", line 52, in <listcomp>
    data = [self.dataset[idx] for idx in possibly_batched_index]
  File "/Users/ammaraljerwi/research/deepsphere-adams/deepsphere_unet/dataset.py", line 29, in __getitem__
    features = _get_features_idx(freqs=self.freqs,
  File "/Users/ammaraljerwi/research/deepsphere-adams/deepsphere_unet/dataset.py", line 103, in _get_features_idx
    feature_data = handler.read(feature_path)
  File "/Users/ammaraljerwi/anaconda3/envs/cmb-ml/lib/python3.9/site-packages/cmbml/core/asset_handlers/healpy_map_handler.py", line 58, in read
    raise FileNotFoundError(f"This map file cannot be found: {path}")
FileNotFoundError: This map file cannot be found: /Users/ammaraljerwi/research/space/Datasets/I_32_2-2/Simulation/Train/sim0000/obs_30_map.fits
[2025-03-28 22:10:05,486][__main__][INFO] - Pipeline completed.
